<?xml version="1.0" encoding="utf-8"?>
<!-- This URDF was automatically created by SolidWorks to URDF Exporter! Originally created by Stephen Brawner (brawner@gmail.com) 
     Commit Version: 1.6.1-11-gaed57c3-dirty  Build Version: 1.6.9385.29558
     For more information, please see http://wiki.ros.org/sw_urdf_exporter -->
<robot
  name="dummy_robot">
  <link
    name="base_link">
    <inertial>
      <origin
        xyz="0.00530439978503028 -5.78503197055102E-05 0.00399549579955868"
        rpy="0 0 0" />
      <mass
        value="0.260196340471791" />
      <inertia
        ixx="0.000326008679465609"
        ixy="-3.84797644506016E-08"
        ixz="-7.6928759292703E-06"
        iyy="0.000195511651864946"
        iyz="-1.62212411695468E-07"
        izz="0.000180867390019727" />
    </inertial>
    <visual>
      <origin
        xyz="0 0 0"
        rpy="0 0 0" />
      <geometry>
        <mesh
          filename="package://dummy_robot/meshes/base_link.STL" />
      </geometry>
      <material
        name="">
        <color
          rgba="0.752941176470588 0.752941176470588 0.752941176470588 1" />
      </material>
    </visual>
    <collision>
      <origin
        xyz="0 0 0"
        rpy="0 0 0" />
      <geometry>
        <mesh
          filename="package://dummy_robot/meshes/base_link.STL" />
      </geometry>
    </collision>
  </link>
  <link
    name="left_shoulder">
    <inertial>
      <origin
        xyz="8.02717027417743E-05 0.0139773890538528 0.000610849214574077"
        rpy="0 0 0" />
      <mass
        value="0.0097065679798793" />
      <inertia
        ixx="6.52473606592951E-06"
        ixy="-1.05363145903596E-08"
        ixz="-6.16393664536725E-07"
        iyy="5.41452809820975E-06"
        iyz="-8.01789332000665E-08"
        izz="1.91512220091499E-06" />
    </inertial>
    <visual>
      <origin
        xyz="0 0 0"
        rpy="0 0 0" />
      <geometry>
        <mesh
          filename="package://dummy_robot/meshes/left_shoulder.STL" />
      </geometry>
      <material
        name="">
        <color
          rgba="1 1 1 1" />
      </material>
    </visual>
    <collision>
      <origin
        xyz="0 0 0"
        rpy="0 0 0" />
      <geometry>
        <mesh
          filename="package://dummy_robot/meshes/left_shoulder.STL" />
      </geometry>
    </collision>
  </link>
  <joint
    name="left_shoulder_joint"
    type="revolute">
    <origin
      xyz="0.016 0.0749 0.049968"
      rpy="0 0 0" />
    <parent
      link="base_link" />
    <child
      link="left_shoulder" />
    <axis
      xyz="0 -1 0" />
    <limit
      lower="-3.14"
      upper="3.14"
      effort="100"
      velocity="100" />
  </joint>
  <link
    name="left_arm">
    <inertial>
      <origin
        xyz="0.0340743092630281 -0.0192083892573478 -0.0331995010498208"
        rpy="0 0 0" />
      <mass
        value="0.0906636812084868" />
      <inertia
        ixx="1.73146976715666E-05"
        ixy="6.78812285071821E-06"
        ixz="2.55514100387685E-06"
        iyy="2.82733581135195E-05"
        iyz="-1.84784026608631E-06"
        izz="3.16681842088576E-05" />
    </inertial>
    <visual>
      <origin
        xyz="0 0 0"
        rpy="0 0 0" />
      <geometry>
        <mesh
          filename="package://dummy_robot/meshes/left_arm.STL" />
      </geometry>
      <material
        name="">
        <color
          rgba="0.792156862745098 0.819607843137255 0.933333333333333 1" />
      </material>
    </visual>
    <collision>
      <origin
        xyz="0 0 0"
        rpy="0 0 0" />
      <geometry>
        <mesh
          filename="package://dummy_robot/meshes/left_arm.STL" />
      </geometry>
    </collision>
  </link>
  <joint
    name="left_arm_joint"
    type="revolute">
    <origin
      xyz="0.0032572 0.0275 0.024787"
      rpy="0 0 0" />
    <parent
      link="left_shoulder" />
    <child
      link="left_arm" />
    <axis
      xyz="-0.13029 0 -0.99148" />
    <limit
      lower="-3.14"
      upper="3.14"
      effort="100"
      velocity="100" />
  </joint>
  <link
    name="left_hand">
    <inertial>
      <origin
        xyz="0.0219004827439188 0.0172569414258233 4.868999660812E-05"
        rpy="0 0 0" />
      <mass
        value="0.00970656797987933" />
      <inertia
        ixx="4.82175837443693E-06"
        ixy="-1.34315153295321E-06"
        ixz="-9.25949257927567E-09"
        iyy="2.44944725476105E-06"
        iyz="2.59086970956647E-07"
        izz="6.58318073585636E-06" />
    </inertial>
    <visual>
      <origin
        xyz="0 0 0"
        rpy="0 0 0" />
      <geometry>
        <mesh
          filename="package://dummy_robot/meshes/left_hand.STL" />
      </geometry>
      <material
        name="">
        <color
          rgba="1 1 1 1" />
      </material>
    </visual>
    <collision>
      <origin
        xyz="0 0 0"
        rpy="0 0 0" />
      <geometry>
        <mesh
          filename="package://dummy_robot/meshes/left_hand.STL" />
      </geometry>
    </collision>
  </link>
  <joint
    name="left_hand_joint"
    type="revolute">
    <origin
      xyz="0.056618 -0.061357 -0.040119"
      rpy="0 0 0" />
    <parent
      link="left_arm" />
    <child
      link="left_hand" />
    <axis
      xyz="0.38857 0.92 -0.051063" />
    <limit
      lower="-3.14"
      upper="3.14"
      effort="100"
      velocity="100" />
  </joint>
  <link
    name="right_shoulder">
    <inertial>
      <origin
        xyz="-7.65274492987023E-05 -0.0139773890538528 -0.000611329582719838"
        rpy="0 0 0" />
      <mass
        value="0.00970656797987936" />
      <inertia
        ixx="6.53211630820216E-06"
        ixy="-1.00448508385269E-08"
        ixz="-5.88104254871476E-07"
        iyy="5.41452809820978E-06"
        iyz="-8.02419854308083E-08"
        izz="1.90774195864237E-06" />
    </inertial>
    <visual>
      <origin
        xyz="0 0 0"
        rpy="0 0 0" />
      <geometry>
        <mesh
          filename="package://dummy_robot/meshes/right_shoulder.STL" />
      </geometry>
      <material
        name="">
        <color
          rgba="1 1 1 1" />
      </material>
    </visual>
    <collision>
      <origin
        xyz="0 0 0"
        rpy="0 0 0" />
      <geometry>
        <mesh
          filename="package://dummy_robot/meshes/right_shoulder.STL" />
      </geometry>
    </collision>
  </link>
  <joint
    name="right_shoulder_joint"
    type="revolute">
    <origin
      xyz="0.016 -0.0749 0.049968"
      rpy="0 0 0" />
    <parent
      link="base_link" />
    <child
      link="right_shoulder" />
    <axis
      xyz="0 1 0" />
    <limit
      lower="-3.14"
      upper="3.14"
      effort="100"
      velocity="100" />
  </joint>
  <link
    name="right_arm">
    <inertial>
      <origin
        xyz="0.0380365314008329 -0.0247474159251424 0.0239377383403235"
        rpy="0 0 0" />
      <mass
        value="0.0906636814036701" />
      <inertia
        ixx="1.99532631240314E-05"
        ixy="8.57629983164971E-06"
        ixz="3.93868893673188E-07"
        iyy="2.5126812132576E-05"
        iyz="-9.71619705193093E-07"
        izz="3.21761648505198E-05" />
    </inertial>
    <visual>
      <origin
        xyz="0 0 0"
        rpy="0 0 0" />
      <geometry>
        <mesh
          filename="package://dummy_robot/meshes/right_arm.STL" />
      </geometry>
      <material
        name="">
        <color
          rgba="1 1 1 1" />
      </material>
    </visual>
    <collision>
      <origin
        xyz="0 0 0"
        rpy="0 0 0" />
      <geometry>
        <mesh
          filename="package://dummy_robot/meshes/right_arm.STL" />
      </geometry>
    </collision>
  </link>
  <joint
    name="right_arm_joint"
    type="revolute">
    <origin
      xyz="-0.0031053 -0.0275 -0.024806"
      rpy="0 0 0" />
    <parent
      link="right_shoulder" />
    <child
      link="right_arm" />
    <axis
      xyz="0.12421 0 0.99226" />
    <limit
      lower="-3.14"
      upper="3.14"
      effort="100"
      velocity="100" />
  </joint>
  <link
    name="right_hand">
    <inertial>
      <origin
        xyz="-0.00686285977351564 -0.026450717740458 -0.00554041778663455"
        rpy="0 0 0" />
      <mass
        value="0.00970656797987935" />
      <inertia
        ixx="4.33865404707442E-06"
        ixy="-1.89452975250622E-06"
        ixz="6.10117946446929E-07"
        iyy="3.29400646261338E-06"
        iyz="-1.06550532534925E-07"
        izz="6.22172585536649E-06" />
    </inertial>
    <visual>
      <origin
        xyz="0 0 0"
        rpy="0 0 0" />
      <geometry>
        <mesh
          filename="package://dummy_robot/meshes/right_hand.STL" />
      </geometry>
      <material
        name="">
        <color
          rgba="1 1 1 1" />
      </material>
    </visual>
    <collision>
      <origin
        xyz="0 0 0"
        rpy="0 0 0" />
      <geometry>
        <mesh
          filename="package://dummy_robot/meshes/right_hand.STL" />
      </geometry>
    </collision>
  </link>
  <joint
    name="right_hand_joint"
    type="revolute">
    <origin
      xyz="0.08628 -0.025652 0.021852"
      rpy="0 0 0" />
    <parent
      link="right_arm" />
    <child
      link="right_hand" />
    <axis
      xyz="-0.62604 -0.77585 0.078368" />
    <limit
      lower="-3.14"
      upper="3.14"
      effort="100"
      velocity="100" />
  </joint>
  <link
    name="left_leg">
    <inertial>
      <origin
        xyz="-0.0231919495539611 0.0129280743272274 -0.0225601371730468"
        rpy="0 0 0" />
      <mass
        value="0.0194131359597587" />
      <inertia
        ixx="8.43985826684452E-06"
        ixy="3.93735192824584E-08"
        ixz="-7.06356937642739E-08"
        iyy="8.93745083192274E-06"
        iyz="-9.73544267452638E-07"
        izz="1.03314636313413E-05" />
    </inertial>
    <visual>
      <origin
        xyz="0 0 0"
        rpy="0 0 0" />
      <geometry>
        <mesh
          filename="package://dummy_robot/meshes/left_leg.STL" />
      </geometry>
      <material
        name="">
        <color
          rgba="1 1 1 1" />
      </material>
    </visual>
    <collision>
      <origin
        xyz="0 0 0"
        rpy="0 0 0" />
      <geometry>
        <mesh
          filename="package://dummy_robot/meshes/left_leg.STL" />
      </geometry>
    </collision>
  </link>
  <joint
    name="left_leg_joint"
    type="revolute">
    <origin
      xyz="0.0149 0.0385 -0.060532"
      rpy="0 0 0" />
    <parent
      link="base_link" />
    <child
      link="left_leg" />
    <axis
      xyz="-1 0 0" />
    <limit
      lower="-3.14"
      upper="3.14"
      effort="100"
      velocity="100" />
  </joint>
  <link
    name="left_limb">
    <inertial>
      <origin
        xyz="0.00490533384482933 -0.00345726775704958 -0.0476727026077802"
        rpy="0 0 0" />
      <mass
        value="0.0832912988386294" />
      <inertia
        ixx="2.63852190204483E-05"
        ixy="-8.72416475871179E-07"
        ixz="1.5648438005591E-06"
        iyy="2.02891416156911E-05"
        iyz="4.61301844352045E-06"
        izz="1.4587253143042E-05" />
    </inertial>
    <visual>
      <origin
        xyz="0 0 0"
        rpy="0 0 0" />
      <geometry>
        <mesh
          filename="package://dummy_robot/meshes/left_limb.STL" />
      </geometry>
      <material
        name="">
        <color
          rgba="1 1 1 1" />
      </material>
    </visual>
    <collision>
      <origin
        xyz="0 0 0"
        rpy="0 0 0" />
      <geometry>
        <mesh
          filename="package://dummy_robot/meshes/left_limb.STL" />
      </geometry>
    </collision>
  </link>
  <joint
    name="left_limb_joint"
    type="revolute">
    <origin
      xyz="-0.0235 0.047155 -0.033248"
      rpy="0 0 0" />
    <parent
      link="left_leg" />
    <child
      link="left_limb" />
    <axis
      xyz="0 -0.87347 -0.48688" />
    <limit
      lower="-3.14"
      upper="3.14"
      effort="100"
      velocity="100" />
  </joint>
  <link
    name="left_knee">
    <inertial>
      <origin
        xyz="-0.0107828039412312 -0.0100475787608216 -0.0326889058865978"
        rpy="0 0 0" />
      <mass
        value="0.0194131359597587" />
      <inertia
        ixx="8.76983259466402E-06"
        ixy="-4.31800490661163E-07"
        ixz="7.07563215984027E-07"
        iyy="8.9909343429337E-06"
        iyz="-9.14645792963964E-07"
        izz="9.94800579251099E-06" />
    </inertial>
    <visual>
      <origin
        xyz="0 0 0"
        rpy="0 0 0" />
      <geometry>
        <mesh
          filename="package://dummy_robot/meshes/left_knee.STL" />
      </geometry>
      <material
        name="">
        <color
          rgba="1 1 1 1" />
      </material>
    </visual>
    <collision>
      <origin
        xyz="0 0 0"
        rpy="0 0 0" />
      <geometry>
        <mesh
          filename="package://dummy_robot/meshes/left_knee.STL" />
      </geometry>
    </collision>
  </link>
  <joint
    name="left_knee_joint"
    type="revolute">
    <origin
      xyz="0.0098098 0.038902 -0.06979"
      rpy="0 0 0" />
    <parent
      link="left_limb" />
    <child
      link="left_knee" />
    <axis
      xyz="0 -0.87347 -0.48688" />
    <limit
      lower="-3.14"
      upper="3.14"
      effort="100"
      velocity="100" />
  </joint>
  <link
    name="left_foot">
    <inertial>
      <origin
        xyz="0.0250896473458811 0.0152479073950542 -0.0164974394576959"
        rpy="0 0 0" />
      <mass
        value="0.0628331790483873" />
      <inertia
        ixx="1.77145018732018E-05"
        ixy="-1.30040641111851E-07"
        ixz="3.76301535131418E-06"
        iyy="1.48031326399674E-05"
        iyz="-1.13780869460818E-07"
        izz="1.97272864743942E-05" />
    </inertial>
    <visual>
      <origin
        xyz="0 0 0"
        rpy="0 0 0" />
      <geometry>
        <mesh
          filename="package://dummy_robot/meshes/left_foot.STL" />
      </geometry>
      <material
        name="">
        <color
          rgba="0.792156862745098 0.819607843137255 0.933333333333333 1" />
      </material>
    </visual>
    <collision>
      <origin
        xyz="0 0 0"
        rpy="0 0 0" />
      <geometry>
        <mesh
          filename="package://dummy_robot/meshes/left_foot.STL" />
      </geometry>
    </collision>
  </link>
  <joint
    name="left_foot_joint"
    type="revolute">
    <origin
      xyz="-0.043872 -0.0035916 -0.044904"
      rpy="0 0 0" />
    <parent
      link="left_knee" />
    <child
      link="left_foot" />
    <axis
      xyz="0.91481 0.19665 -0.35278" />
    <limit
      lower="-3.14"
      upper="3.14"
      effort="100"
      velocity="100" />
  </joint>
  <link
    name="right_leg">
    <inertial>
      <origin
        xyz="-0.0231919495539712 -0.0202630719951378 -0.0162942569145518"
        rpy="0 0 0" />
      <mass
        value="0.0194131359597587" />
      <inertia
        ixx="8.43985826684455E-06"
        ixy="-6.241536342228E-08"
        ixz="-5.14198178051025E-08"
        iyy="9.78372772207625E-06"
        iyz="1.18799186975678E-06"
        izz="9.48518674118785E-06" />
    </inertial>
    <visual>
      <origin
        xyz="0 0 0"
        rpy="0 0 0" />
      <geometry>
        <mesh
          filename="package://dummy_robot/meshes/right_leg.STL" />
      </geometry>
      <material
        name="">
        <color
          rgba="1 1 1 1" />
      </material>
    </visual>
    <collision>
      <origin
        xyz="0 0 0"
        rpy="0 0 0" />
      <geometry>
        <mesh
          filename="package://dummy_robot/meshes/right_leg.STL" />
      </geometry>
    </collision>
  </link>
  <joint
    name="right_leg_joint"
    type="revolute">
    <origin
      xyz="0.0149 -0.0385 -0.060532"
      rpy="0 0 0" />
    <parent
      link="base_link" />
    <child
      link="right_leg" />
    <axis
      xyz="-1 0 0" />
    <limit
      lower="-3.14"
      upper="3.14"
      effort="100"
      velocity="100" />
  </joint>
  <link
    name="right_limb">
    <inertial>
      <origin
        xyz="0.00315412166500978 -0.0142964847797823 -0.0457644597918528"
        rpy="0 0 0" />
      <mass
        value="0.0832912986528664" />
      <inertia
        ixx="2.65142350343062E-05"
        ixy="8.93138844112135E-07"
        ixz="7.359034961212E-07"
        iyy="1.63244370072914E-05"
        iyz="-5.38615761570608E-06"
        izz="1.84229416247173E-05" />
    </inertial>
    <visual>
      <origin
        xyz="0 0 0"
        rpy="0 0 0" />
      <geometry>
        <mesh
          filename="package://dummy_robot/meshes/right_limb.STL" />
      </geometry>
      <material
        name="">
        <color
          rgba="0.792156862745098 0.819607843137255 0.933333333333333 1" />
      </material>
    </visual>
    <collision>
      <origin
        xyz="0 0 0"
        rpy="0 0 0" />
      <geometry>
        <mesh
          filename="package://dummy_robot/meshes/right_limb.STL" />
      </geometry>
    </collision>
  </link>
  <joint
    name="right_limb_point"
    type="revolute">
    <origin
      xyz="-0.0235 -0.056031 -0.013769"
      rpy="0 0 0" />
    <parent
      link="right_leg" />
    <child
      link="right_limb" />
    <axis
      xyz="0 0.63585 -0.77182" />
    <limit
      lower="-3.14"
      upper="3.14"
      effort="100"
      velocity="100" />
  </joint>
  <link
    name="right_knee">
    <inertial>
      <origin
        xyz="0.0181843069406225 0.00135561598487954 -0.0308752417681935"
        rpy="0 0 0" />
      <mass
        value="0.0194131359597587" />
      <inertia
        ixx="9.71755535314504E-06"
        ixy="-9.58284922388481E-07"
        ixz="-7.15309033361238E-07"
        iyy="9.15805106113636E-06"
        iyz="5.34541617100092E-07"
        izz="8.83316631582729E-06" />
    </inertial>
    <visual>
      <origin
        xyz="0 0 0"
        rpy="0 0 0" />
      <geometry>
        <mesh
          filename="package://dummy_robot/meshes/right_knee.STL" />
      </geometry>
      <material
        name="">
        <color
          rgba="1 1 1 1" />
      </material>
    </visual>
    <collision>
      <origin
        xyz="0 0 0"
        rpy="0 0 0" />
      <geometry>
        <mesh
          filename="package://dummy_robot/meshes/right_knee.STL" />
      </geometry>
    </collision>
  </link>
  <joint
    name="right_knee_joint"
    type="revolute">
    <origin
      xyz="0.006308 -0.06194 -0.051028"
      rpy="0 0 0" />
    <parent
      link="right_limb" />
    <child
      link="right_knee" />
    <axis
      xyz="0 0.63585 -0.77182" />
    <limit
      lower="-3.14"
      upper="3.14"
      effort="100"
      velocity="100" />
  </joint>
  <link
    name="right_foot">
    <inertial>
      <origin
        xyz="0.0245376937845771 0.0225912631941112 0.00465574342729203"
        rpy="0 0 0" />
      <mass
        value="0.0628331069592222" />
      <inertia
        ixx="1.7475550381396E-05"
        ixy="-3.00675364640809E-06"
        ixz="2.20105832817186E-06"
        iyy="1.81467326706087E-05"
        iyz="-2.41942250804363E-06"
        izz="1.66229809994363E-05" />
    </inertial>
    <visual>
      <origin
        xyz="0 0 0"
        rpy="0 0 0" />
      <geometry>
        <mesh
          filename="package://dummy_robot/meshes/right_foot.STL" />
      </geometry>
      <material
        name="">
        <color
          rgba="1 1 1 1" />
      </material>
    </visual>
    <collision>
      <origin
        xyz="0 0 0"
        rpy="0 0 0" />
      <geometry>
        <mesh
          filename="package://dummy_robot/meshes/right_foot.STL" />
      </geometry>
    </collision>
  </link>
  <joint
    name="right_foot_joint"
    type="revolute">
    <origin
      xyz="0.019143 -0.026113 -0.053904"
      rpy="0 0 0" />
    <parent
      link="right_knee" />
    <child
      link="right_foot" />
    <axis
      xyz="0.70645 0.54627 0.45003" />
    <limit
      lower="-3.14"
      upper="3.14"
      effort="100"
      velocity="100" />
  </joint>
  <link
    name="head">
    <inertial>
      <origin
        xyz="0.00981671095316355 0.0024613944543207 0.0158925814082566"
        rpy="0 0 0" />
      <mass
        value="0.020219295801448" />
      <inertia
        ixx="6.05202654039109E-06"
        ixy="1.98172423158263E-07"
        ixz="-1.29203811678321E-06"
        iyy="5.31134977560234E-06"
        iyz="-3.23959365880606E-07"
        izz="4.72238329098025E-06" />
    </inertial>
    <visual>
      <origin
        xyz="0 0 0"
        rpy="0 0 0" />
      <geometry>
        <mesh
          filename="package://dummy_robot/meshes/head.STL" />
      </geometry>
      <material
        name="">
        <color
          rgba="1 1 1 1" />
      </material>
    </visual>
    <collision>
      <origin
        xyz="0 0 0"
        rpy="0 0 0" />
      <geometry>
        <mesh
          filename="package://dummy_robot/meshes/head.STL" />
      </geometry>
    </collision>
  </link>
  <joint
    name="head_joint"
    type="revolute">
    <origin
      xyz="0.01675 -0.0005 0.087118"
      rpy="0 0 0" />
    <parent
      link="base_link" />
    <child
      link="head" />
    <axis
      xyz="0 0 -1" />
    <limit
      lower="-3.14"
      upper="3.14"
      effort="100"
      velocity="100" />
  </joint>
</robot>